Workbook

Sheet ESTOQUE APOSTILAS
A1: APOSTILAS | B1: ENTRADAS | C1: SAIDAS | D1: ESTOQUE FINAL | E1: PERDA | F1: VALOR | G1: VALOR TOTAL PERDA | H1: ATUALIZADA EM | I1: Coluna 1
A2: {=UNIQUE('MOVIMENTAÇÃO'!$C2:$C999)} -> A AUTORIDADE DO CRENTE | B2: =SUMIFS('MOVIMENTAÇÃO'!$D:$D,'MOVIMENTAÇÃO'!$C:$C,A2,'MOVIMENTAÇÃO'!$B:$B,"ENTRADA") -> 17 | C2: =SUMIFS('MOVIMENTAÇÃO'!$D:$D,'MOVIMENTAÇÃO'!$C:$C,A2,'MOVIMENTAÇÃO'!$B:$B,"SAIDA") -> 15 | D2: =B2-C2 -> 2 | E2: =SUMIFS('MOVIMENTAÇÃO'!$D:$D,'MOVIMENTAÇÃO'!$C:$C,A2,'MOVIMENTAÇÃO'!$B:$B,"PERDA") -> 0 | F2: =SUMIFS('MOVIMENTAÇÃO'!$E:$E,'MOVIMENTAÇÃO'!$C:$C,A2,'MOVIMENTAÇÃO'!$B:$B,"PERDA") -> 0 | G2: =E2*F2 -> 0 | H2: =TODAY() -> 46259
A3: BHP | B3: =SUMIFS('MOVIMENTAÇÃO'!$D:$D,'MOVIMENTAÇÃO'!$C:$C,A3,'MOVIMENTAÇÃO'!$B:$B,"ENTRADA") -> 254 | C3: =SUMIFS('MOVIMENTAÇÃO'!$D:$D,'MOVIMENTAÇÃO'!$C:$C,A3,'MOVIMENTAÇÃO'!$B:$B,"SAIDA") -> 250 | D3: =B3-C3 -> 4 | E3: =SUMIFS('MOVIMENTAÇÃO'!$D:$D,'MOVIMENTAÇÃO'!$C:$C,A3,'MOVIMENTAÇÃO'!$B:$B,"PERDA") -> 0 | F3: =SUMIFS('MOVIMENTAÇÃO'!$E:$E,'MOVIMENTAÇÃO'!$C:$C,A3,'MOVIMENTAÇÃO'!$B:$B,"PERDA") -> 0 | G3: =E3*F3 -> 0
A4: CADERNO BUSINESS ( VOLNEY) | B4: =SUMIFS('MOVIMENTAÇÃO'!$D:$D,'MOVIMENTAÇÃO'!$C:$C,A4,'MOVIMENTAÇÃO'!$B:$B,"ENTRADA") -> 25 | C4: =SUMIFS('MOVIMENTAÇÃO'!$D:$D,'MOVIMENTAÇÃO'!$C:$C,A4,'MOVIMENTAÇÃO'!$B:$B,"SAIDA") -> 1 | D4: =B4-C4 -> 24 | E4: =SUMIFS('MOVIMENTAÇÃO'!$D:$D,'MOVIMENTAÇÃO'!$C:$C,A4,'MOVIMENTAÇÃO'!$B:$B,"PERDA") -> 0 | F4: =SUMIFS('MOVIMENTAÇÃO'!$E:$E,'MOVIMENTAÇÃO'!$C:$C,A4,'MOVIMENTAÇÃO'!$B:$B,"PERDA") -> 0 | G4: =E4*F4 -> 0
A5: CHAVES DO PODER E AUTORRESPONSABILIDADE | B5: =SUMIFS('MOVIMENTAÇÃO'!$D:$D,'MOVIMENTAÇÃO'!$C:$C,A5,'MOVIMENTAÇÃO'!$B:$B,"ENTRADA") -> 500 | C5: =SUMIFS('MOVIMENTAÇÃO'!$D:$D,'MOVIMENTAÇÃO'!$C:$C,A5,'MOVIMENTAÇÃO'!$B:$B,"SAIDA") -> 391 | D5: =B5-C5 -> 109 | E5: =SUMIFS('MOVIMENTAÇÃO'!$D:$D,'MOVIMENTAÇÃO'!$C:$C,A5,'MOVIMENTAÇÃO'!$B:$B,"PERDA") -> 0 | F5: =SUMIFS('MOVIMENTAÇÃO'!$E:$E,'MOVIMENTAÇÃO'!$C:$C,A5,'MOVIMENTAÇÃO'!$B:$B,"PERDA") -> 0 | G5: =E5*F5 -> 0
A6: CIS | B6: =SUMIFS('MOVIMENTAÇÃO'!$D:$D,'MOVIMENTAÇÃO'!$C:$C,A6,'MOVIMENTAÇÃO'!$B:$B,"ENTRADA") -> 4515 | C6: =SUMIFS('MOVIMENTAÇÃO'!$D:$D,'MOVIMENTAÇÃO'!$C:$C,A6,'MOVIMENTAÇÃO'!$B:$B,"SAIDA") -> 4362 | D6: =B6-C6 -> 153 | E6: =SUMIFS('MOVIMENTAÇÃO'!$D:$D,'MOVIMENTAÇÃO'!$C:$C,A6,'MOVIMENTAÇÃO'!$B:$B,"PERDA") -> 428 | F6: =SUMIFS('MOVIMENTAÇÃO'!$E:$E,'MOVIMENTAÇÃO'!$C:$C,A6,'MOVIMENTAÇÃO'!$B:$B,"PERDA") -> 35.95 | G6: =E6*F6 -> 15386.6
A7: COACHING PARA METAS | B7: =SUMIFS('MOVIMENTAÇÃO'!$D:$D,'MOVIMENTAÇÃO'!$C:$C,A7,'MOVIMENTAÇÃO'!$B:$B,"ENTRADA") -> 113 | C7: =SUMIFS('MOVIMENTAÇÃO'!$D:$D,'MOVIMENTAÇÃO'!$C:$C,A7,'MOVIMENTAÇÃO'!$B:$B,"SAIDA") -> 62 | D7: =B7-C7 -> 51 | E7: =SUMIFS('MOVIMENTAÇÃO'!$D:$D,'MOVIMENTAÇÃO'!$C:$C,A7,'MOVIMENTAÇÃO'!$B:$B,"PERDA") -> 0 | F7: =SUMIFS('MOVIMENTAÇÃO'!$E:$E,'MOVIMENTAÇÃO'!$C:$C,A7,'MOVIMENTAÇÃO'!$B:$B,"PERDA") -> 0 | G7: =E7*F7 -> 0
A8: DECIFRE E INFLUENCIE PESSOAS | B8: =SUMIFS('MOVIMENTAÇÃO'!$D:$D,'MOVIMENTAÇÃO'!$C:$C,A8,'MOVIMENTAÇÃO'!$B:$B,"ENTRADA") -> 45 | C8: =SUMIFS('MOVIMENTAÇÃO'!$D:$D,'MOVIMENTAÇÃO'!$C:$C,A8,'MOVIMENTAÇÃO'!$B:$B,"SAIDA") -> 0 | D8: =B8-C8 -> 45 | E8: =SUMIFS('MOVIMENTAÇÃO'!$D:$D,'MOVIMENTAÇÃO'!$C:$C,A8,'MOVIMENTAÇÃO'!$B:$B,"PERDA") -> 0 | F8: =SUMIFS('MOVIMENTAÇÃO'!$E:$E,'MOVIMENTAÇÃO'!$C:$C,A8,'MOVIMENTAÇÃO'!$B:$B,"PERDA") -> 0 | G8: =E8*F8 -> 0
A9: EDUCAR AMAR E DAR LIMITES | B9: =SUMIFS('MOVIMENTAÇÃO'!$D:$D,'MOVIMENTAÇÃO'!$C:$C,A9,'MOVIMENTAÇÃO'!$B:$B,"ENTRADA") -> 100 | C9: =SUMIFS('MOVIMENTAÇÃO'!$D:$D,'MOVIMENTAÇÃO'!$C:$C,A9,'MOVIMENTAÇÃO'!$B:$B,"SAIDA") -> 72 | D9: =B9-C9 -> 28 | E9: =SUMIFS('MOVIMENTAÇÃO'!$D:$D,'MOVIMENTAÇÃO'!$C:$C,A9,'MOVIMENTAÇÃO'!$B:$B,"PERDA") -> 0 | F9: =SUMIFS('MOVIMENTAÇÃO'!$E:$E,'MOVIMENTAÇÃO'!$C:$C,A9,'MOVIMENTAÇÃO'!$B:$B,"PERDA") -> 0 | G9: =E9*F9 -> 0
A10: FCIS | B10: =SUMIFS('MOVIMENTAÇÃO'!$D:$D,'MOVIMENTAÇÃO'!$C:$C,A10,'MOVIMENTAÇÃO'!$B:$B,"ENTRADA") -> 224 | C10: =SUMIFS('MOVIMENTAÇÃO'!$D:$D,'MOVIMENTAÇÃO'!$C:$C,A10,'MOVIMENTAÇÃO'!$B:$B,"SAIDA") -> 224 | D10: =B10-C10 -> 0 | E10: =SUMIFS('MOVIMENTAÇÃO'!$D:$D,'MOVIMENTAÇÃO'!$C:$C,A10,'MOVIMENTAÇÃO'!$B:$B,"PERDA") -> 0 | F10: =SUMIFS('MOVIMENTAÇÃO'!$E:$E,'MOVIMENTAÇÃO'!$C:$C,A10,'MOVIMENTAÇÃO'!$B:$B,"PERDA") -> 0 | G10: =E10*F10 -> 0
A11: FCIS NOVA | B11: =SUMIFS('MOVIMENTAÇÃO'!$D:$D,'MOVIMENTAÇÃO'!$C:$C,A11,'MOVIMENTAÇÃO'!$B:$B,"ENTRADA") -> 203 | C11: =SUMIFS('MOVIMENTAÇÃO'!$D:$D,'MOVIMENTAÇÃO'!$C:$C,A11,'MOVIMENTAÇÃO'!$B:$B,"SAIDA") -> 177 | D11: =B11-C11 -> 26 | E11: =SUMIFS('MOVIMENTAÇÃO'!$D:$D,'MOVIMENTAÇÃO'!$C:$C,A11,'MOVIMENTAÇÃO'!$B:$B,"PERDA") -> 0 | F11: =SUMIFS('MOVIMENTAÇÃO'!$E:$E,'MOVIMENTAÇÃO'!$C:$C,A11,'MOVIMENTAÇÃO'!$B:$B,"PERDA") -> 0 | G11: =E11*F11 -> 0
A12: FGCPC- COMPANY | B12: =SUMIFS('MOVIMENTAÇÃO'!$D:$D,'MOVIMENTAÇÃO'!$C:$C,A12,'MOVIMENTAÇÃO'!$B:$B,"ENTRADA") -> 50 | C12: =SUMIFS('MOVIMENTAÇÃO'!$D:$D,'MOVIMENTAÇÃO'!$C:$C,A12,'MOVIMENTAÇÃO'!$B:$B,"SAIDA") -> 25 | D12: =B12-C12 -> 25 | E12: =SUMIFS('MOVIMENTAÇÃO'!$D:$D,'MOVIMENTAÇÃO'!$C:$C,A12,'MOVIMENTAÇÃO'!$B:$B,"PERDA") -> 0 | F12: =SUMIFS('MOVIMENTAÇÃO'!$E:$E,'MOVIMENTAÇÃO'!$C:$C,A12,'MOVIMENTAÇÃO'!$B:$B,"PERDA") -> 0 | G12: =E12*F12 -> 0
A13: FOCO NA PRÁTICA | B13: =SUMIFS('MOVIMENTAÇÃO'!$D:$D,'MOVIMENTAÇÃO'!$C:$C,A13,'MOVIMENTAÇÃO'!$B:$B,"ENTRADA") -> 9 | C13: =SUMIFS('MOVIMENTAÇÃO'!$D:$D,'MOVIMENTAÇÃO'!$C:$C,A13,'MOVIMENTAÇÃO'!$B:$B,"SAIDA") -> 0 | D13: =B13-C13 -> 9 | E13: =SUMIFS('MOVIMENTAÇÃO'!$D:$D,'MOVIMENTAÇÃO'!$C:$C,A13,'MOVIMENTAÇÃO'!$B:$B,"PERDA") -> 0 | F13: =SUMIFS('MOVIMENTAÇÃO'!$E:$E,'MOVIMENTAÇÃO'!$C:$C,A13,'MOVIMENTAÇÃO'!$B:$B,"PERDA") -> 0 | G13: =E13*F13 -> 0
A14: FOP | B14: =SUMIFS('MOVIMENTAÇÃO'!$D:$D,'MOVIMENTAÇÃO'!$C:$C,A14,'MOVIMENTAÇÃO'!$B:$B,"ENTRADA") -> 342 | C14: =SUMIFS('MOVIMENTAÇÃO'!$D:$D,'MOVIMENTAÇÃO'!$C:$C,A14,'MOVIMENTAÇÃO'!$B:$B,"SAIDA") -> 267 | D14: =B14-C14 -> 75 | E14: =SUMIFS('MOVIMENTAÇÃO'!$D:$D,'MOVIMENTAÇÃO'!$C:$C,A14,'MOVIMENTAÇÃO'!$B:$B,"PERDA") -> 0 | F14: =SUMIFS('MOVIMENTAÇÃO'!$E:$E,'MOVIMENTAÇÃO'!$C:$C,A14,'MOVIMENTAÇÃO'!$B:$B,"PERDA") -> 0 | G14: =E14*F14 -> 0
... A38: ML5 NOVA | B38: =SUMIFS('MOVIMENTAÇÃO'!$D:$D,'MOVIMENTAÇÃO'!$C:$C,A38,'MOVIMENTAÇÃO'!$B:$B,"ENTRADA") -> 40 | C38: =SUMIFS('MOVIMENTAÇÃO'!$D:$D,'MOVIMENTAÇÃO'!$C:$C,A38,'MOVIMENTAÇÃO'!$B:$B,"SAIDA") -> 17 | D38: =B38-C38 -> 23 | E38: =SUMIFS('MOVIMENTAÇÃO'!$D:$D,'MOVIMENTAÇÃO'!$C:$C,A38,'MOVIMENTAÇÃO'!$B:$B,"PERDA") -> 0 | F38: =SUMIFS('MOVIMENTAÇÃO'!$E:$E,'MOVIMENTAÇÃO'!$C:$C,A38,'MOVIMENTAÇÃO'!$B:$B,"PERDA") -> 0 | G38: =E38*F38 -> 0
B39: =SUMIFS('MOVIMENTAÇÃO'!$D:$D,'MOVIMENTAÇÃO'!$C:$C,A39,'MOVIMENTAÇÃO'!$B:$B,"ENTRADA") -> 0 | C39: =SUMIFS('MOVIMENTAÇÃO'!$D:$D,'MOVIMENTAÇÃO'!$C:$C,A39,'MOVIMENTAÇÃO'!$B:$B,"SAIDA") -> 0 | D39: =B39-C39 -> 0 | E39: =SUMIFS('MOVIMENTAÇÃO'!$D:$D,'MOVIMENTAÇÃO'!$C:$C,A39,'MOVIMENTAÇÃO'!$B:$B,"PERDA") -> 0 | F39: =SUMIFS('MOVIMENTAÇÃO'!$E:$E,'MOVIMENTAÇÃO'!$C:$C,A39,'MOVIMENTAÇÃO'!$B:$B,"PERDA") -> 0 | G39: =E39*F39 -> 0
F40: =SUMIFS('MOVIMENTAÇÃO'!$E:$E,'MOVIMENTAÇÃO'!$C:$C,A40,'MOVIMENTAÇÃO'!$B:$B,"PERDA") -> 0 | G40: =E40*F40 -> 0
F41: =SUMIFS('MOVIMENTAÇÃO'!$E:$E,'MOVIMENTAÇÃO'!$C:$C,A41,'MOVIMENTAÇÃO'!$B:$B,"PERDA") -> 0 | G41: =E41*F41 -> 0
F42: =SUMIFS('MOVIMENTAÇÃO'!$E:$E,'MOVIMENTAÇÃO'!$C:$C,A42,'MOVIMENTAÇÃO'!$B:$B,"PERDA") -> 0 | G42: =E42*F42 -> 0
F43: =SUMIFS('MOVIMENTAÇÃO'!$E:$E,'MOVIMENTAÇÃO'!$C:$C,A43,'MOVIMENTAÇÃO'!$B:$B,"PERDA") -> 0 | G43: =E43*F43 -> 0
F44: =SUMIFS('MOVIMENTAÇÃO'!$E:$E,'MOVIMENTAÇÃO'!$C:$C,A44,'MOVIMENTAÇÃO'!$B:$B,"PERDA") -> 0 | G44: =E44*F44 -> 0
F45: =SUMIFS('MOVIMENTAÇÃO'!$E:$E,'MOVIMENTAÇÃO'!$C:$C,A45,'MOVIMENTAÇÃO'!$B:$B,"PERDA") -> 0 | G45: =E45*F45 -> 0
F46: =SUMIFS('MOVIMENTAÇÃO'!$E:$E,'MOVIMENTAÇÃO'!$C:$C,A46,'MOVIMENTAÇÃO'!$B:$B,"PERDA") -> 0 | G46: =E46*F46 -> 0
F47: =SUMIFS('MOVIMENTAÇÃO'!$E:$E,'MOVIMENTAÇÃO'!$C:$C,A47,'MOVIMENTAÇÃO'!$B:$B,"PERDA") -> 0 | G47: =E47*F47 -> 0
F48: =SUMIFS('MOVIMENTAÇÃO'!$E:$E,'MOVIMENTAÇÃO'!$C:$C,A48,'MOVIMENTAÇÃO'!$B:$B,"PERDA") -> 0 | G48: =E48*F48 -> 0
F49: =SUMIFS('MOVIMENTAÇÃO'!$E:$E,'MOVIMENTAÇÃO'!$C:$C,A49,'MOVIMENTAÇÃO'!$B:$B,"PERDA") -> 0 | G49: =E49*F49 -> 0
F50: =SUMIFS('MOVIMENTAÇÃO'!$E:$E,'MOVIMENTAÇÃO'!$C:$C,A50,'MOVIMENTAÇÃO'!$B:$B,"PERDA") -> 0 | G50: =E50*F50 -> 0
F51: =SUMIFS('MOVIMENTAÇÃO'!$E:$E,'MOVIMENTAÇÃO'!$C:$C,A51,'MOVIMENTAÇÃO'!$B:$B,"PERDA") -> 0 | G51: =E51*F51 -> 0
... F999: =SUMIFS('MOVIMENTAÇÃO'!$E:$E,'MOVIMENTAÇÃO'!$C:$C,A999,'MOVIMENTAÇÃO'!$B:$B,"PERDA") -> 0 | G999: =E999*F999 -> 0

Sheet MOVIMENTAÇÃO
A1: data | B1: TIPO | C1: APOSTILA | D1: QUANTIDADE | E1: UF
A2: 45966 | B2: ENTRADA | C2: A AUTORIDADE DO CRENTE | D2: 15
A3: 45223 | B3: ENTRADA | C3: BHP | D3: 74
A4: 45358 | B4: SAIDA | C4: BHP | D4: 20
A5: 45455 | B5: SAIDA | C5: BHP | D5: 9
A6: 45469 | B6: ENTRADA | C6: BHP | D6: 50
A7: 45555 | B7: SAIDA | C7: BHP | D7: 24
A8: 45637 | B8: SAIDA | C8: BHP | D8: 28
A9: 45775 | B9: ENTRADA | C9: BHP | D9: 60
A10: 45796 | B10: SAIDA | C10: BHP | D10: 65
A11: 45887 | B11: ENTRADA | C11: BHP | D11: 40
A12: 45889 | B12: SAIDA | C12: BHP | D12: 21
A13: 45972 | B13: SAIDA | C13: BHP | D13: 15
... A33: 45637 | B33: SAIDA | C33: CIS | D33: 325
A34: 45637 | B34: ENTRADA | C34: CIS | D34: 310 | F34: ajuste
A35: 45695 | B35: SAIDA | C35: CIS | D35: 336
A36: 45695 | B36: ENTRADA | C36: CIS | D36: 300
A37: 45705 | B37: ENTRADA | C37: CIS | D37: 200
A38: 45705 | B38: SAIDA | C38: CIS | D38: 344
A39: 45740 | B39: ENTRADA | C39: CIS | D39: 1000
A40: 45765 | B40: SAIDA | C40: CIS | D40: 300
A41: 45898 | B41: SAIDA | C41: CIS | D41: 456
A42: 45898 | B42: ENTRADA | C42: CIS | D42: 37
A43: 45923 | B43: ENTRADA | C43: CIS | D43: 124
A44: 45987 | B44: SAIDA | C44: CIS | D44: 133
A45: 46007 | B45: PERDA | C45: CIS | D45: 428 | E45: 35.95
A46: 46007 | B46: SAIDA | C46: CIS | D46: 428
A47: 45351 | B47: ENTRADA | C47: COACHING PARA METAS | D47: 13
A48: 45385 | B48: ENTRADA | C48: COACHING PARA METAS | D48: 100
A49: 45395 | B49: SAIDA | C49: COACHING PARA METAS | D49: 62
A50: 45294 | B50: ENTRADA | C50: DECIFRE E INFLUENCIE PESSOAS | D50: 39
A51: 45951 | B51: ENTRADA | C51: DECIFRE E INFLUENCIE PESSOAS | D51: 6
A52: 45597 | B52: ENTRADA | C52: EDUCAR AMAR E DAR LIMITES | D52: 60
A53: 45608 | B53: SAIDA | C53: EDUCAR AMAR E DAR LIMITES | D53: 34
A54: 45951 | B54: SAIDA | C54: EDUCAR AMAR E DAR LIMITES | D54: 7
A55: 45223 | B55: ENTRADA | C55: FCIS | D55: 60
A56: 45266 | B56: SAIDA | C56: FCIS | D56: 50
A57: 45369 | B57: SAIDA | C57: FCIS | D57: 10
... A79: 45469 | B79: ENTRADA | C79: FOP | D79: 100
A80: 23;09;2024 | B80: SAIDA | C80: FOP | D80: 25
...

Sheet Estoque de Materiais
D1: ATUALIZADA EM | E1: =TODAY() -> 46259
A3: MATERIAIS | B3: ENTRADA | C3: SAIDA | D3: ESTOQUE FINAL | E3: UF
A4: {=UNIQUE('Movimentação Estoque'!$C$2:$C1001)} -> ALGODÃO | B4: =SUMIFS('Movimentação Estoque'!$D:$D,'Movimentação Estoque'!$C:$C,A4,'Movimentação Estoque'!$B:$B,"ENTRADA") -> 10 | C4: =SUMIFS('Movimentação Estoque'!$D:$D,'Movimentação Estoque'!$C:$C,A4,'Movimentação Estoque'!$B:$B,"SAIDA") -> 3 | D4: =B4-C4 -> 7 | E4: {=_xlfn.XLOOKUP('Movimentação Estoque'!C:C,E4,'Movimentação Estoque'!D:D,'Movimentação Estoque'!E:E,"UF")} -> #VALUE!
A5: BALÃO JUNINO PEQUENO | B5: =SUMIFS('Movimentação Estoque'!$D:$D,'Movimentação Estoque'!$C:$C,A5,'Movimentação Estoque'!$B:$B,"ENTRADA") -> 4 | C5: =SUMIFS('Movimentação Estoque'!$D:$D,'Movimentação Estoque'!$C:$C,A5,'Movimentação Estoque'!$B:$B,"SAIDA") -> 0 | D5: =B5-C5 -> 4
A6: BALÃO LETRA C | B6: =SUMIFS('Movimentação Estoque'!$D:$D,'Movimentação Estoque'!$C:$C,A6,'Movimentação Estoque'!$B:$B,"ENTRADA") -> 1 | C6: =SUMIFS('Movimentação Estoque'!$D:$D,'Movimentação Estoque'!$C:$C,A6,'Movimentação Estoque'!$B:$B,"SAIDA") -> 0 | D6: =B6-C6 -> 1 | E6: UND
A7: BALÃO Nº 1 | B7: =SUMIFS('Movimentação Estoque'!$D:$D,'Movimentação Estoque'!$C:$C,A7,'Movimentação Estoque'!$B:$B,"ENTRADA") -> 1 | C7: =SUMIFS('Movimentação Estoque'!$D:$D,'Movimentação Estoque'!$C:$C,A7,'Movimentação Estoque'!$B:$B,"SAIDA") -> 0 | D7: =B7-C7 -> 1 | E7: UND
A8: BANDEIRAS DO BRASIL | B8: =SUMIFS('Movimentação Estoque'!$D:$D,'Movimentação Estoque'!$C:$C,A8,'Movimentação Estoque'!$B:$B,"ENTRADA") -> 29 | C8: =SUMIFS('Movimentação Estoque'!$D:$D,'Movimentação Estoque'!$C:$C,A8,'Movimentação Estoque'!$B:$B,"SAIDA") -> 0 | D8: =B8-C8 -> 29 | E8: UND
A9: BANDEIROLAS DO BRASIL | B9: =SUMIFS('Movimentação Estoque'!$D:$D,'Movimentação Estoque'!$C:$C,A9,'Movimentação Estoque'!$B:$B,"ENTRADA") -> 6 | C9: =SUMIFS('Movimentação Estoque'!$D:$D,'Movimentação Estoque'!$C:$C,A9,'Movimentação Estoque'!$B:$B,"SAIDA") -> 0 | D9: =B9-C9 -> 6 | E9: UND
A10: BANDEIROLAS FLORIDA | B10: =SUMIFS('Movimentação Estoque'!$D:$D,'Movimentação Estoque'!$C:$C,A10,'Movimentação Estoque'!$B:$B,"ENTRADA") -> 1 | C10: =SUMIFS('Movimentação Estoque'!$D:$D,'Movimentação Estoque'!$C:$C,A10,'Movimentação Estoque'!$B:$B,"SAIDA") -> 0 | D10: =B10-C10 -> 1 | E10: UND
A11: BAOAS FESTAS | B11: =SUMIFS('Movimentação Estoque'!$D:$D,'Movimentação Estoque'!$C:$C,A11,'Movimentação Estoque'!$B:$B,"ENTRADA") -> 1 | C11: =SUMIFS('Movimentação Estoque'!$D:$D,'Movimentação Estoque'!$C:$C,A11,'Movimentação Estoque'!$B:$B,"SAIDA") -> 0 | D11: =B11-C11 -> 1 | E11: UND
A12: Barra de chocolate Konpenhagem | B12: =SUMIFS('Movimentação Estoque'!$D:$D,'Movimentação Estoque'!$C:$C,A12,'Movimentação Estoque'!$B:$B,"ENTRADA") -> 40 | C12: =SUMIFS('Movimentação Estoque'!$D:$D,'Movimentação Estoque'!$C:$C,A12,'Movimentação Estoque'!$B:$B,"SAIDA") -> 18 | D12: =B12-C12 -> 22 | E12: UND
A13: BLOCO DE NOTAS FEBRACIS | B13: =SUMIFS('Movimentação Estoque'!$D:$D,'Movimentação Estoque'!$C:$C,A13,'Movimentação Estoque'!$B:$B,"ENTRADA") -> 41 | C13: =SUMIFS('Movimentação Estoque'!$D:$D,'Movimentação Estoque'!$C:$C,A13,'Movimentação Estoque'!$B:$B,"SAIDA") -> 33 | D13: =B13-C13 -> 8 | E13: UND
A14: BLOCO DE NOTAS HOMENS | B14: =SUMIFS('Movimentação Estoque'!$D:$D,'Movimentação Estoque'!$C:$C,A14,'Movimentação Estoque'!$B:$B,"ENTRADA") -> 308 | C14: =SUMIFS('Movimentação Estoque'!$D:$D,'Movimentação Estoque'!$C:$C,A14,'Movimentação Estoque'!$B:$B,"SAIDA") -> 240 | D14: =B14-C14 -> 68
A15: BLOCO DE NOTAS MAESTRIA | B15: =SUMIFS('Movimentação Estoque'!$D:$D,'Movimentação Estoque'!$C:$C,A15,'Movimentação Estoque'!$B:$B,"ENTRADA") -> 24 | C15: =SUMIFS('Movimentação Estoque'!$D:$D,'Movimentação Estoque'!$C:$C,A15,'Movimentação Estoque'!$B:$B,"SAIDA") -> 0 | D15: =B15-C15 -> 24 | E15: CX
A16: BLOCO DE NOTAS MULHERES | B16: =SUMIFS('Movimentação Estoque'!$D:$D,'Movimentação Estoque'!$C:$C,A16,'Movimentação Estoque'!$B:$B,"ENTRADA") -> 368 | C16: =SUMIFS('Movimentação Estoque'!$D:$D,'Movimentação Estoque'!$C:$C,A16,'Movimentação Estoque'!$B:$B,"SAIDA") -> 338 | D16: =B16-C16 -> 30 | E16: UND
A17: BOLA DE VIVIL | B17: =SUMIFS('Movimentação Estoque'!$D:$D,'Movimentação Estoque'!$C:$C,A17,'Movimentação Estoque'!$B:$B,"ENTRADA") -> 0 | C17: =SUMIFS('Movimentação Estoque'!$D:$D,'Movimentação Estoque'!$C:$C,A17,'Movimentação Estoque'!$B:$B,"SAIDA") -> 10 | D17: =B17-C17 -> -10 | E17: UND
A18: BOLAS ROSA | B18: =SUMIFS('Movimentação Estoque'!$D:$D,'Movimentação Estoque'!$C:$C,A18,'Movimentação Estoque'!$B:$B,"ENTRADA") -> 10 | C18: =SUMIFS('Movimentação Estoque'!$D:$D,'Movimentação Estoque'!$C:$C,A18,'Movimentação Estoque'!$B:$B,"SAIDA") -> 0 | D18: =B18-C18 -> 10 | E18: UND
A19: BOMBA MANUAL | B19: =SUMIFS('Movimentação Estoque'!$D:$D,'Movimentação Estoque'!$C:$C,A19,'Movimentação Estoque'!$B:$B,"ENTRADA") -> 0 | C19: =SUMIFS('Movimentação Estoque'!$D:$D,'Movimentação Estoque'!$C:$C,A19,'Movimentação Estoque'!$B:$B,"SAIDA") -> 2 | D19: =B19-C19 -> -2 | E19: UND
A20: Buzina de pressão | B20: =SUMIFS('Movimentação Estoque'!$D:$D,'Movimentação Estoque'!$C:$C,A20,'Movimentação Estoque'!$B:$B,"ENTRADA") -> 2 | C20: =SUMIFS('Movimentação Estoque'!$D:$D,'Movimentação Estoque'!$C:$C,A20,'Movimentação Estoque'!$B:$B,"SAIDA") -> 0 | D20: =B20-C20 -> 2 | E20: UND
A21: Cachepots Para Mini Suculentas (rótulos) | B21: =SUMIFS('Movimentação Estoque'!$D:$D,'Movimentação Estoque'!$C:$C,A21,'Movimentação Estoque'!$B:$B,"ENTRADA") -> 16 | C21: =SUMIFS('Movimentação Estoque'!$D:$D,'Movimentação Estoque'!$C:$C,A21,'Movimentação Estoque'!$B:$B,"SAIDA") -> 0 | D21: =B21-C21 -> 16 | E21: UND
A22: CADERNO EMPRESARIAL | B22: =SUMIFS('Movimentação Estoque'!$D:$D,'Movimentação Estoque'!$C:$C,A22,'Movimentação Estoque'!$B:$B,"ENTRADA") -> 55 | C22: =SUMIFS('Movimentação Estoque'!$D:$D,'Movimentação Estoque'!$C:$C,A22,'Movimentação Estoque'!$B:$B,"SAIDA") -> 31 | D22: =B22-C22 -> 24 | E22: UND
A23: CAIXA ANIVERSARIO DE DULCE | B23: =SUMIFS('Movimentação Estoque'!$D:$D,'Movimentação Estoque'!$C:$C,A23,'Movimentação Estoque'!$B:$B,"ENTRADA") -> 6 | C23: =SUMIFS('Movimentação Estoque'!$D:$D,'Movimentação Estoque'!$C:$C,A23,'Movimentação Estoque'!$B:$B,"SAIDA") -> 0 | D23: =B23-C23 -> 6 | E23: UND
A24: CAIXA BEGE MULHERES ALTA PERFORMANCE | B24: =SUMIFS('Movimentação Estoque'!$D:$D,'Movimentação Estoque'!$C:$C,A24,'Movimentação Estoque'!$B:$B,"ENTRADA") -> 8 | C24: =SUMIFS('Movimentação Estoque'!$D:$D,'Movimentação Estoque'!$C:$C,A24,'Movimentação Estoque'!$B:$B,"SAIDA") -> 0 | D24: =B24-C24 -> 8 | E24: UND
A25: CAIXA BRIGADEIRO IF | B25: =SUMIFS('Movimentação Estoque'!$D:$D,'Movimentação Estoque'!$C:$C,A25,'Movimentação Estoque'!$B:$B,"ENTRADA") -> 13 | C25: =SUMIFS('Movimentação Estoque'!$D:$D,'Movimentação Estoque'!$C:$C,A25,'Movimentação Estoque'!$B:$B,"SAIDA") -> 0 | D25: =B25-C25 -> 13 | E25: UND
A26: CAIXA CIS GLOBAL | B26: =SUMIFS('Movimentação Estoque'!$D:$D,'Movimentação Estoque'!$C:$C,A26,'Movimentação Estoque'!$B:$B,"ENTRADA") -> 1 | C26: =SUMIFS('Movimentação Estoque'!$D:$D,'Movimentação Estoque'!$C:$C,A26,'Movimentação Estoque'!$B:$B,"SAIDA") -> 0 | D26: =B26-C26 -> 1 | E26: UND
... A47: CAPA DE CADEIRA BLACK | B47: =SUMIFS('Movimentação Estoque'!$D:$D,'Movimentação Estoque'!$C:$C,A47,'Movimentação Estoque'!$B:$B,"ENTRADA") -> 50 | C47: =SUMIFS('Movimentação Estoque'!$D:$D,'Movimentação Estoque'!$C:$C,A47,'Movimentação Estoque'!$B:$B,"SAIDA") -> 0 | D47: =B47-C47 -> 50 | E47: UND
A48: CARTUCHO 964 AMARELO | B48: =SUMIFS('Movimentação Estoque'!$D:$D,'Movimentação Estoque'!$C:$C,A48,'Movimentação Estoque'!$B:$B,"ENTRADA") -> 10 | C48: =SUMIFS('Movimentação Estoque'!$D:$D,'Movimentação Estoque'!$C:$C,A48,'Movimentação Estoque'!$B:$B,"SAIDA") -> 5 | D48: =B48-C48 -> 5
A49: CARTUCHO 964 AZUL | B49: =SUMIFS('Movimentação Estoque'!$D:$D,'Movimentação Estoque'!$C:$C,A49,'Movimentação Estoque'!$B:$B,"ENTRADA") -> 16 | C49: =SUMIFS('Movimentação Estoque'!$D:$D,'Movimentação Estoque'!$C:$C,A49,'Movimentação Estoque'!$B:$B,"SAIDA") -> 11 | D49: =B49-C49 -> 5
A50: CARTUCHO 964 PRETO | B50: =SUMIFS('Movimentação Estoque'!$D:$D,'Movimentação Estoque'!$C:$C,A50,'Movimentação Estoque'!$B:$B,"ENTRADA") -> 11 | C50: =SUMIFS('Movimentação Estoque'!$D:$D,'Movimentação Estoque'!$C:$C,A50,'Movimentação Estoque'!$B:$B,"SAIDA") -> 6 | D50: =B50-C50 -> 5
A51: CARTUCHO 964 ROSA | B51: =SUMIFS('Movimentação Estoque'!$D:$D,'Movimentação Estoque'!$C:$C,A51,'Movimentação Estoque'!$B:$B,"ENTRADA") -> 11 | C51: =SUMIFS('Movimentação Estoque'!$D:$D,'Movimentação Estoque'!$C:$C,A51,'Movimentação Estoque'!$B:$B,"SAIDA") -> 5 | D51: =B51-C51 -> 6
A52: CHAPEU COPO DO BRASIL | B52: =SUMIFS('Movimentação Estoque'!$D:$D,'Movimentação Estoque'!$C:$C,A52,'Movimentação Estoque'!$B:$B,"ENTRADA") -> 1 | C52: =SUMIFS('Movimentação Estoque'!$D:$D,'Movimentação Estoque'!$C:$C,A52,'Movimentação Estoque'!$B:$B,"SAIDA") -> 0 | D52: =B52-C52 -> 1
A53: CHOCOLATES EM PASTILHAS | B53: =SUMIFS('Movimentação Estoque'!$D:$D,'Movimentação Estoque'!$C:$C,A53,'Movimentação Estoque'!$B:$B,"ENTRADA") -> 1408 | C53: =SUMIFS('Movimentação Estoque'!$D:$D,'Movimentação Estoque'!$C:$C,A53,'Movimentação Estoque'!$B:$B,"SAIDA") -> 689 | D53: =B53-C53 -> 719
A54: CLIP PRATA | B54: =SUMIFS('Movimentação Estoque'!$D:$D,'Movimentação Estoque'!$C:$C,A54,'Movimentação Estoque'!$B:$B,"ENTRADA") -> 1 | C54: =SUMIFS('Movimentação Estoque'!$D:$D,'Movimentação Estoque'!$C:$C,A54,'Movimentação Estoque'!$B:$B,"SAIDA") -> 0 | D54: =B54-C54 -> 1
A55: Cola bastão | B55: =SUMIFS('Movimentação Estoque'!$D:$D,'Movimentação Estoque'!$C:$C,A55,'Movimentação Estoque'!$B:$B,"ENTRADA") -> 9 | C55: =SUMIFS('Movimentação Estoque'!$D:$D,'Movimentação Estoque'!$C:$C,A55,'Movimentação Estoque'!$B:$B,"SAIDA") -> 0 | D55: =B55-C55 -> 9
A56: COLONIA JHONSSON | B56: =SUMIFS('Movimentação Estoque'!$D:$D,'Movimentação Estoque'!$C:$C,A56,'Movimentação Estoque'!$B:$B,"ENTRADA") -> 5 | C56: =SUMIFS('Movimentação Estoque'!$D:$D,'Movimentação Estoque'!$C:$C,A56,'Movimentação Estoque'!$B:$B,"SAIDA") -> 2 | D56: =B56-C56 -> 3
A57: CORDÃO FEBRACIS | B57: =SUMIFS('Movimentação Estoque'!$D:$D,'Movimentação Estoque'!$C:$C,A57,'Movimentação Estoque'!$B:$B,"ENTRADA") -> 3174 | C57: =SUMIFS('Movimentação Estoque'!$D:$D,'Movimentação Estoque'!$C:$C,A57,'Movimentação Estoque'!$B:$B,"SAIDA") -> 1674 | D57: =B57-C57 -> 1500
A58: CORDÃO GOLDEN | B58: =SUMIFS('Movimentação Estoque'!$D:$D,'Movimentação Estoque'!$C:$C,A58,'Movimentação Estoque'!$B:$B,"ENTRADA") -> 472 | C58: =SUMIFS('Movimentação Estoque'!$D:$D,'Movimentação Estoque'!$C:$C,A58,'Movimentação Estoque'!$B:$B,"SAIDA") -> 205 | D58: =B58-C58 -> 267 | E58: Quantidade na caixa preta
A59: CORDÃO GREEN | B59: =SUMIFS('Movimentação Estoque'!$D:$D,'Movimentação Estoque'!$C:$C,A59,'Movimentação Estoque'!$B:$B,"ENTRADA") -> 397 | C59: =SUMIFS('Movimentação Estoque'!$D:$D,'Movimentação Estoque'!$C:$C,A59,'Movimentação Estoque'!$B:$B,"SAIDA") -> 123 | D59: =B59-C59 -> 274 | E59: Quantidade na caixa preta
A60: CORDÃO GREEN ANTIGO | B60: =SUMIFS('Movimentação Estoque'!$D:$D,'Movimentação Estoque'!$C:$C,A60,'Movimentação Estoque'!$B:$B,"ENTRADA") -> 60 | C60: =SUMIFS('Movimentação Estoque'!$D:$D,'Movimentação Estoque'!$C:$C,A60,'Movimentação Estoque'!$B:$B,"SAIDA") -> 0 | D60: =B60-C60 -> 60 | E60: Quantidade na caixa preta
A61: CORDÃO MAESTRIA | B61: =SUMIFS('Movimentação Estoque'!$D:$D,'Movimentação Estoque'!$C:$C,A61,'Movimentação Estoque'!$B:$B,"ENTRADA") -> 56 | C61: =SUMIFS('Movimentação Estoque'!$D:$D,'Movimentação Estoque'!$C:$C,A61,'Movimentação Estoque'!$B:$B,"SAIDA") -> 0 | D61: =B61-C61 -> 56
...

Sheet Movimentação Estoque
A1: DATA | B1: TIPO | C1: APOSTILA | D1: QUANTIDADE | E1: UF
A2: 45889 | B2: SAIDA | C2: ALGODÃO | D2: 2 | E2: UND | H2: CAMISAS MAESTRIA
A3: 45924 | B3: ENTRADA | C3: ALGODÃO | D3: 10 | E3: UND | H3: P | I3: 6
A4: 45937 | B4: SAIDA | C4: ALGODÃO | D4: 1 | E4: UND | H4: M | I4: 2
A5: 46009 | B5: ENTRADA | C5: BALÃO JUNINO PEQUENO | D5: 4 | E5: UND | H5: G | I5: 3
A6: 46009 | B6: ENTRADA | C6: BALÃO LETRA C | D6: 1 | E6: UND | H6: GG | I6: 1
A7: 46009 | B7: ENTRADA | C7: BALÃO Nº 1 | D7: 1 | E7: UND
A8: 46009 | B8: ENTRADA | C8: BANDEIRAS DO BRASIL | D8: 29 | E8: UND
A9: 46009 | B9: ENTRADA | C9: BANDEIROLAS DO BRASIL | D9: 6 | E9: UND
A10: 46009 | B10: ENTRADA | C10: BANDEIROLAS FLORIDA | D10: 1 | E10: UND
A11: 46009 | B11: ENTRADA | C11: BAOAS FESTAS | D11: 1 | E11: UND
A12: 46009 | B12: ENTRADA | C12: Barra de chocolate Konpenhagem | D12: 17 | E12: UND
A13: 46034 | B13: SAIDA | C13: Barra de chocolate Konpenhagem | D13: 4 | E13: UND
A14: 46042 | B14: ENTRADA | C14: Barra de chocolate Konpenhagem | D14: 20
A15: 46042 | B15: SAIDA | C15: Barra de chocolate Konpenhagem | D15: 14
A16: 46044 | B16: ENTRADA | C16: Barra de chocolate Konpenhagem | D16: 3
A17: 45951 | B17: ENTRADA | C17: BLOCO DE NOTAS FEBRACIS | D17: 26 | E17: UND
A18: 46079 | B18: ENTRADA | C18: BLOCO DE NOTAS FEBRACIS | D18: 15 | E18: UND
A19: 46079 | B19: SAIDA | C19: BLOCO DE NOTAS FEBRACIS | D19: 33 | E19: UND
A20: 45952 | B20: ENTRADA | C20: BLOCO DE NOTAS HOMENS | D20: 108 | E20: UND
A21: 45958 | B21: SAIDA | C21: BLOCO DE NOTAS HOMENS | D21: 108 | E21: UND
A22: 46013 | B22: ENTRADA | C22: BLOCO DE NOTAS MAESTRIA | D22: 10 | E22: UND
A23: 46056 | B23: ENTRADA | C23: BLOCO DE NOTAS MAESTRIA | D23: 14 | E23: UND
A24: 45952 | B24: ENTRADA | C24: BLOCO DE NOTAS MULHERES | D24: 68 | E24: UND
A25: 45958 | B25: SAIDA | C25: BLOCO DE NOTAS MULHERES | D25: 68 | E25: UND
A26: 45889 | B26: SAIDA | C26: BOLA DE VIVIL | D26: 10 | E26: UND
A27: 46009 | B27: ENTRADA | C27: BOLAS ROSA | D27: 10 | E27: UND
A28: 45889 | B28: SAIDA | C28: BOMBA MANUAL | D28: 2 | E28: UND
... A33: 46059 | B33: ENTRADA | C33: CAIXA BEGE MULHERES ALTA PERFORMANCE | D33: 8 | E33: UND
A34: 46059 | B34: ENTRADA | C34: CAIXA BRIGADEIRO IF | D34: 13
A35: 46008 | B35: ENTRADA | C35: CAIXA CIS GLOBAL | D35: 1 | E35: UND
A36: 46055 | B36: ENTRADA | C36: CAIXA COM SUPORTE DE CELULAR | D36: 6
A37: 45979 | B37: ENTRADA | C37: CAIXA DAY DULCE BORDO | D37: 10 | E37: UND
A38: 46034 | B38: ENTRADA | C38: CAIXA DAY DULCE BORDO | D38: 10 | E38: UND
A39: 46042 | B39: SAIDA | C39: CAIXA DAY DULCE BORDO | D39: 15
A40: 46044 | B40: ENTRADA | C40: CAIXA DAY DULCE BORDO | D40: 10
A41: 46008 | B41: ENTRADA | C41: CAIXA DO LIVRO DE DULCE | D41: 1 | E41: UND
A42: 46034 | B42: ENTRADA | C42: CAIXA GGB p/ brigadeiro | D42: 30 | E42: UND
A43: 46049 | B43: SAIDA | C43: CAIXA GGB p/ brigadeiro | D43: 30 | E43: UND
A44: 46008 | B44: ENTRADA | C44: CAIXA IF | D44: 2 | E44: UND
...

Sheet Cadastro de Itens
A1: ITENS
A2: ALGODÃO
A3: BALÃO JUNINO PEQUENO
A4: BALÃO LETRA C
A5: BALÃO Nº 1
A6: BANDEIRAS DO BRASIL
A7: BANDEIROLAS DO BRASIL
A8: BANDEIROLAS FLORIDA
A9: BAOAS FESTAS
A10: Barra de chocolate Konpenhagem
A11: BLOCO DE NOTAS FEBRACIS
A12: BLOCO DE NOTAS HOMENS
... A184: ESPUMA PARA HEDSET

Sheet Material if
A1: MATERIAIS PARA O IF | B1: Coluna 1 | C1: Coluna 2
A2: CRACHÁ GOLDEN | B2: 427 | C2: UND
A3: CRACHÁ GREEN | B3: 375 | C3: UND
A4: CRACHÁ STAFF | B4: 50 | C4: UND
A5: CRACHÁ FEBRACIS | B5: 600 | C5: UND
A6: CORDÃO GREEN | B6: 300 | C6: UND
A7: CORDÃO GOLDEN | B7: 300 | C7: UND
A8: CORDÃO PRETO | B8: 500 | C8: UND
A9: LIGA ELASTICA | B9: 1200 | C9: UND
A10: PILOTE VERDE | B10: 12 | C10: UND
A11: PILOTE PRETO | B11: 12 | C11: UND
A12: PILOTE AZUL | B12: 12 | C12: UND
A13: PILOTE VERMELHO | B13: 12 | C13: UND
... A40: MOCHILA MAESTRIA | B40: 12 | C40: UND

Sheet Materiais H&M Recife
A1: MATERIAIS H&M ENVIADOS PARA RECIFE | B1: UF | C1: QUANT | D1: VL. UNT | E1: FRETE | F1: VL.TOTAL | G1: Coluna 1 | H1: Column 10 | I1: NF | J1: COMPENSAÇÃO | K1: Coluna 2
A2: CRACHÁ HOMENS | B2: UND | C2: 100 | D2: 0.92 | F2: =(C2*D2)+E2 -> 92 | G2: TRUE | I2: https://nfe.etransparencia.com.br/sp.ferraz/nfe/PublicTempStorage/sis_00000000000454198900000_lay3.pdf | J2: COMPENSADO
A3: CRACHÁ MULHERES | B3: UND | C3: 200 | D3: 0.92 | F3: =(C3*D3)+E3 -> 184 | G3: TRUE | I3: https://nfe.etransparencia.com.br/sp.ferraz/nfe/PublicTempStorage/sis_00000000000454198900000_lay3.pdf | J3: COMPENSADO
A4: PASTA HOMENS | B4: UND | C4: 100 | D4: 2.34 | F4: =(C4*D4)+E4 -> 234 | G4: TRUE | I4: https://nfe.etransparencia.com.br/sp.ferraz/nfe/PublicTempStorage/sis_00000000000448036700000_lay3.pdf | J4: COMPENSADO
A5: PASTA MULHERES | B5: UND | C5: 182 | D5: 2.34 | F5: =(C5*D5)+E5 -> 425.88 | G5: TRUE | I5: https://nfe.etransparencia.com.br/sp.ferraz/nfe/PublicTempStorage/sis_00000000000448036700000_lay3.pdf | J5: COMPENSADO
A6: ESPELHOS | B6: UND | C6: 184 | D6: 5.36 | F6: =(C6*D6)+E6 -> 986.24 | G6: TRUE | I6: elo 7 | J6: COMPENSADO
A7: CAIXINHAS MULHERES | B7: UND | C7: 19 | D7: 18.9 | F7: =(C7*D7)+E7 -> 359.1 | G7: TRUE | I7: enviado no grupo | J7: COMPENSADO
A8: BLOCO DE NOTAS HOMENS | B8: UND | C8: 108 | D8: 10.53 | F8: =(C8*D8)+E8 -> 1137.24 | G8: TRUE | I8: file:///C:/Users/finan/Downloads/NFS-e_2164_FEBRACIS_SALVADOR.pdf | J8: COMPENSADO
A9: BLOCO DE NOTAS MULHERES | B9: UND | C9: 68 | D9: 10.53 | F9: =(C9*D9)+E9 -> 716.04 | G9: TRUE | I9: file:///C:/Users/finan/Downloads/NFS-e_2164_FEBRACIS_SALVADOR.pdf | J9: COMPENSADO
A10: CAMISAS MULHERES | B10: UND | C10: 2 | D10: 34.8 | F10: =(C10*D10)+E10 -> 69.6 | G10: TRUE | H10: P | I10: file:///C:/Users/finan/Downloads/Pedido%203743795%20cedro%20diamantino.pdf | J10: COMPENSADO
A11: CAMISAS MULHERES | B11: UND | C11: 9 | D11: 34.8 | F11: =(C11*D11)+E11 -> 313.2 | G11: TRUE | H11: G | I11: file:///C:/Users/finan/Downloads/Pedido%203743795%20cedro%20diamantino.pdf | J11: COMPENSADO
A12: CAMISAS MULHERES | B12: UND | C12: 5 | D12: 34.8 | F12: =(C12*D12)+E12 -> 174 | G12: TRUE | H12: GG | I12: file:///C:/Users/finan/Downloads/Pedido%203743795%20cedro%20diamantino.pdf | J12: COMPENSADO
A13: CAMISA HOMENS | B13: UND | C13: 3 | D13: 34.8 | F13: =(C13*D13)+E13 -> 104.4 | G13: TRUE | H13: G | I13: file:///C:/Users/finan/Downloads/Pedido%203743795%20cedro%20diamantino.pdf | J13: COMPENSADO
A14: CAMISA HOMENS | B14: UND | C14: 2 | D14: 34.8 | F14: =(C14*D14)+E14 -> 69.6 | G14: TRUE | H14: GG | I14: file:///C:/Users/finan/Downloads/Pedido%203743795%20cedro%20diamantino.pdf | J14: COMPENSADO
A15: PULSEIRAS HOMENS | B15: UND | C15: 100 | D15: 0.47 | F15: =(C15*D15)+E15 -> 47 | G15: TRUE | J15: COMPENSADO
A16: PULSEIRAS MULHERES | B16: UND | C16: 200 | D16: 0.47 | F16: =(C16*D16)+E16 -> 94 | G16: TRUE | J16: COMPENSADO
A17: LIVROS DULCE | B17: UND | C17: 16 | D17: 0 | F17: =(C17*D17)+E17 -> 0 | G17: TRUE | H17: primeira remessa da compra | J17: COMPENSADO
A18: INOVE PRATAS BRINDES | B18: UND | C18: 20 | D18: 0 | F18: =(C18*D18)+E18 -> 0 | G18: TRUE | H18: Brinde de parceria | J18: COMPENSADO
A19: FRETE | C19: 1 | D19: 300 | F19: =(C19*D19)+E19 -> 300 | G19: TRUE | J19: COMPENSADO
A20: APOSTILA MASTER | B20: UND | C20: 2 | D20: 104.29 | F20: =(C20*D20)+E20 -> 208.58 | G20: TRUE | J20: COMPENSADO | K20: 5514.88
A21: Caderno mentoria business | B21: UND | C21: 30 | D21: 37 | F21: =(C21*D21)+E21 -> 1110 | G21: TRUE | J21: PENDENTE
A22: Caixa mentoria business | B22: UND | C22: 30 | D22: 45 | F22: =(C22*D22)+E22 -> 1350 | G22: TRUE | J22: PENDENTE
A23: caneta mentoria business | B23: UND | C23: 30 | D23: 6 | F23: =(C23*D23)+E23 -> 180 | G23: TRUE | J23: PENDENTE
A24: APOSTILA BHP | B24: UND | C24: 14 | D24: 53.9 | F24: =(C24*D24)+E24 -> 754.6 | G24: TRUE | J24: PENDENTE
A25: CAIXA MAESTRIA | B25: UND | C25: 5 | D25: 45 | F25: =(C25*D25)+E25 -> 225 | G25: TRUE | J25: PENDENTE
A26: MOSLEKINE MAESTRIA UNIQUE | B26: UND | C26: 5 | D26: 29.34 | F26: =(C26*D26)+E26 -> 146.7 | G26: TRUE | J26: PENDENTE
A27: CANETA MAESTRUA UNIQUE | B27: UND | C27: 5 | D27: 15.09 | F27: =(C27*D27)+E27 -> 75.45 | G27: TRUE | J27: PENDENTE
A28: CAPA MAESTRIA | B28: UND | C28: 6 | D28: 13 | F28: =(C28*D28)+E28 -> 78 | G28: TRUE | J28: PENDENTE
A29: BLOCO DE NOTAS MAESTRIA | B29: UND | C29: 6 | D29: 14 | F29: =(C29*D29)+E29 -> 84 | G29: TRUE | J29: PENDENTE
A30: CORDÃO MAESTRIA | B30: UND | C30: 6 | D30: 7 | F30: =(C30*D30)+E30 -> 42 | G30: TRUE | J30: PENDENTE
A31: CRACHÁ MAESTRIA | B31: UND | C31: 6 | D31: 4.5 | F31: =(C31*D31)+E31 -> 27 | G31: TRUE | J31: PENDENTE | K31: 4072.75
A32: TROFÉUS MAESTRIA | B32: UND | C32: 5 | F32: =(C32*D32)+E32 -> 0 | G32: FALSE
F33: =(C33*D33)+E33 -> 0 | G33: FALSE
F34: =(C34*D34)+E34 -> 0 | G34: FALSE
F35: =(C35*D35)+E35 -> 0 | G35: FALSE
F36: =(C36*D36)+E36 -> 0 | G36: FALSE
F37: =(C37*D37)+E37 -> 0 | G37: FALSE
F38: =(C38*D38)+E38 -> 0 | G38: FALSE
F39: =(C39*D39)+E39 -> 0 | G39: FALSE
E40: TOTAL | F40: =SUM(F2:F39) -> 9587.63 | G40: FALSE
...
